Workbook

Sheet Декомпозиция
A1: SyncVoice™ Platform — Декомпозиция и оценка по специалистам
A2: Ставка: 3 000 руб./ч (все специалисты) | Разработка с нуля | On-premise, GPU | Буфер 15% отдельной строкой | M2: Ставка: | N2: 3000
A3: № | B3: Функция / Блок | C3: Приор. | D3: Аналит.,ч | E3: Разраб. BE,ч | F3: Разраб. FE,ч | G3: QA,ч | H3: PM,ч | I3: DevOps,ч | J3: Итого,ч | K3: Стоимость, руб. | L3: Примечание
B4: АРХИТЕКТУРА И ПРОЕКТИРОВАНИЕ
A5: 1.1 | B5: Анализ требований ТЗ, проектирование архитектуры | C5: M | D5: 20 | E5: 16 | H5: 12 | J5: =SUM(D5:I5) | K5: =J5*$N$2 | L5: Модульная архитектура: ASR→NMT→TTS pipeline
A6: 1.2 | B6: Проектирование API-контрактов (streaming + REST) | C6: M | D6: 16 | E6: 24 | F6: 8 | H6: 4 | J6: =SUM(D6:I6) | K6: =J6*$N$2 | L6: WebSocket/WebRTC протоколы, REST для AdminPortal
A7: 1.3 | B7: Проектирование БД (глоссарии, сессии, логи, аудит) | C7: M | D7: 12 | E7: 16 | H7: 4 | J7: =SUM(D7:I7) | K7: =J7*$N$2 | L7: PostgreSQL: glossary, sessions, audit_log, users
A8: 1.4 | B8: Настройка проекта (CI/CD, Docker dev, lint) | C8: M | E8: 8 | F8: 8 | H8: 4 | I8: 16 | J8: =SUM(D8:I8) | K8: =J8*$N$2 | L8: Docker Compose для dev, pre-commit hooks
B9: VOICECORE™ ASR ENGINE
A10: 2.1 | B10: Интеграция streaming ASR (Whisper / faster-whisper) | C10: M | D10: 8 | E10: 60 | G10: 16 | H10: 4 | I10: 8 | J10: =SUM(D10:I10) | K10: =J10*$N$2 | L10: Real-time inference, GPU оптимизация
A11: 2.2 | B11: SmartPause™ — детекция пауз и сегментация речи | C11: M | D11: 8 | E11: 40 | G11: 16 | H11: 4 | I11: 4 | J11: =SUM(D11:I11) | K11: =J11*$N$2 | L11: VAD + пороговая логика, буферизация
A12: 2.3 | B12: Speaker adaptation / fine-tune (5 спикеров) | C12: S | D12: 8 | E12: 48 | G12: 24 | H12: 4 | I12: 8 | J12: =SUM(D12:I12) | K12: =J12*$N$2 | L12: ⚠ Кол-во спикеров не определено, буфер на 5
A13: 2.4 | B13: Языковые модели EN, RU, HI | C13: M | D13: 4 | E13: 24 | G13: 16 | H13: 4 | I13: 4 | J13: =SUM(D13:I13) | K13: =J13*$N$2 | L13: Загрузка, тест, калибровка по каждому языку
B14: NEUROTRANSLATE™ NMT MODULE
A15: 3.1 | B15: Интеграция SeamlessM4T / NLLB | C15: M | D15: 16 | E15: 40 | H15: 8 | I15: 8 | J15: =SUM(D15:I15) | K15: =J15*$N$2 | L15: Encoder-decoder, выбор модели, бенчмарк
A16: 3.2 | B16: Streaming mode с partial results | C16: M | D16: 8 | E16: 48 | G16: 24 | H16: 4 | I16: 8 | J16: =SUM(D16:I16) | K16: =J16*$N$2 | L16: Инкрементальный перевод для <2 сек latency
A17: 3.3 | B17: Интеграция с GlossaryAI™ — приоритет терминов | C17: M | D17: 12 | E17: 60 | G17: 24 | H17: 4 | I17: 4 | J17: =SUM(D17:I17) | K17: =J17*$N$2 | L17: Constrained decoding / post-processing терминов
A18: 3.4 | B18: Контекстное окно 512 токенов | C18: M | D18: 4 | E18: 32 | G18: 16 | H18: 4 | I18: 4 | J18: =SUM(D18:I18) | K18: =J18*$N$2 | L18: Скользящее окно, кеширование контекста
A19: 3.5 | B19: 200+ языковых пар (zero-shot для редких) | C19: S | D19: 8 | E19: 40 | G19: 32 | H19: 4 | I19: 4 | J19: =SUM(D19:I19) | K19: =J19*$N$2 | L19: ⚠ Качество неравномерное, гарантия на EN↔RU/HI
B20: VOICESYNTH™ TTS ENGINE
A21: 4.1 | B21: Интеграция нейросетевого TTS (Coqui/XTTS) | C21: M | D21: 12 | E21: 40 | H21: 8 | I21: 8 | J21: =SUM(D21:I21) | K21: =J21*$N$2 | L21: Выбор модели, бенчмарк MOS >4.0
A22: 4.2 | B22: Streaming mode (~600ms latency) | C22: M | D22: 4 | E22: 48 | G22: 24 | H22: 4 | I22: 8 | J22: =SUM(D22:I22) | K22: =J22*$N$2 | L22: Chunk-based генерация, буферизация
A23: 4.3 | B23: Подбор и настройка голосов (MOS >4.0) | C23: M | D23: 8 | E23: 60 | G23: 32 | H23: 4 | I23: 4 | J23: =SUM(D23:I23) | K23: =J23*$N$2 | L23: A/B тестирование голосов, субъективная оценка
A24: 4.4 | B24: Premium голоса — расширенный пакет | C24: C | D24: 4 | E24: 24 | G24: 16 | H24: 4 | I24: 4 | J24: =SUM(D24:I24) | K24: =J24*$N$2 | L24: Опциональный модуль
B25: STREAMORCHESTRATOR™
A26: 5.1 | B26: WebSocket / WebRTC оркестрация потоков | C26: M | D26: 12 | E26: 80 | G26: 32 | H26: 8 | I26: 16 | J26: =SUM(D26:I26) | K26: =J26*$N$2 | L26: Основной pipeline: аудиовход→ASR→NMT→TTS→аудиовыход
A27: 5.2 | B27: Pipeline управление (ASR→NMT→TTS chain) | C27: M | D27: 8 | E27: 60 | G27: 24 | H27: 4 | I27: 8 | J27: =SUM(D27:I27) | K27: =J27*$N$2 | L27: Очередь, backpressure, graceful degradation
A28: 5.3 | B28: Параллельная обработка 2 аудиопотоков | C28: M | D28: 4 | E28: 40 | G28: 24 | H28: 4 | I28: 8 | J28: =SUM(D28:I28) | K28: =J28*$N$2 | L28: Thread/process pool, распределение GPU
A29: 5.4 | B29: Мониторинг latency, автоматический fallback | C29: S | D29: 4 | E29: 32 | G29: 16 | H29: 4 | I29: 8 | J29: =SUM(D29:I29) | K29: =J29*$N$2 | L29: Prometheus метрики, алерты >2 сек
B30: GLOSSARYAI™ (>2000 ЗАПИСЕЙ)
A31: 6.1 | B31: CRUD глоссариев — импорт Excel, CSV, TBX | C31: M | D31: 12 | E31: 32 | F31: 16 | G31: 20 | H31: 4 | I31: 4 | J31: =SUM(D31:I31) | K31: =J31*$N$2 | L31: Парсинг, валидация, дедупликация
A32: 6.2 | B32: Извлечение терминов из PDF (NER/regex) | C32: S | D32: 8 | E32: 60 | G32: 24 | H32: 4 | I32: 4 | J32: =SUM(D32:I32) | K32: =J32*$N$2 | L32: PyMuPDF + SpaCy NER для хим. соединений
A33: 6.3 | B33: Фонетические транскрипции для TTS | C33: M | D33: 4 | E33: 32 | G33: 16 | H33: 4 | J33: =SUM(D33:I33) | K33: =J33*$N$2 | L33: IPA генерация, интеграция с VoiceSynth
A34: 6.4 | B34: Версионирование, правила «не переводить» | C34: M | D34: 8 | E34: 32 | F34: 8 | G34: 16 | H34: 4 | I34: 4 | J34: =SUM(D34:I34) | K34: =J34*$N$2 | L34: Git-like версионирование, whitelist кодов
A35: 6.5 | B35: Валидация глоссария >2000 записей | C35: M | D35: 8 | G35: 32 | H35: 4 | J35: =SUM(D35:I35) | K35: =J35*$N$2 | L35: ⚠ Большой объём, ручная + автоматическая проверка
B36: SYNCBRIDGE™ (ИНТЕГРАЦИЯ ВКС)
A37: 7.1 | B37: Zoom Language Interpretation API | C37: M | D37: 12 | E37: 80 | G37: 40 | H37: 8 | I37: 12 | J37: =SUM(D37:I37) | K37: =J37*$N$2 | L37: ⚠ API может иметь ограничения, буфер на workaround
A38: 7.2 | B38: Microsoft Teams Audio API | C38: M | D38: 12 | E38: 80 | G38: 40 | H38: 8 | I38: 12 | J38: =SUM(D38:I38) | K38: =J38*$N$2 | L38: ⚠ Аналогично, Teams API менее зрелый
A39: 7.3 | B39: Управление аудиоканалами + маршрутизация | C39: M | D39: 8 | E39: 40 | G39: 24 | H39: 4 | I39: 8 | J39: =SUM(D39:I39) | K39: =J39*$N$2 | L39: Микширование, громкость оригинала, переключение
B40: ADMINPORTAL™ (ВЕБ-ИНТЕРФЕЙС)
...

Sheet Сводка
A1: Сводная таблица по специалистам — SyncVoice™ Platform
A2: Специалист | B2: Часов | C2: Ставка руб./ч | D2: Стоимость, руб.
A3: Аналитик | B3: ='Декомпозиция'!D67 | C3: ='Декомпозиция'!$N$2 | D3: =B3*C3
A4: Разработчик Back-End | B4: ='Декомпозиция'!E67 | C4: ='Декомпозиция'!$N$2 | D4: =B4*C4
A5: Разработчик Front-End | B5: ='Декомпозиция'!F67 | C5: ='Декомпозиция'!$N$2 | D5: =B5*C5
A6: Тестировщик (QA) | B6: ='Декомпозиция'!G67 | C6: ='Декомпозиция'!$N$2 | D6: =B6*C6
A7: Руководитель проекта | B7: ='Декомпозиция'!H67 | C7: ='Декомпозиция'!$N$2 | D7: =B7*C7
A8: DevOps-инженер | B8: ='Декомпозиция'!I67 | C8: ='Декомпозиция'!$N$2 | D8: =B8*C8
A9: Базовая оценка | B9: =SUM(B3:B8) | C9: ='Декомпозиция'!$N$2 | D9: =B9*C9
A10: Буфер 15% | B10: =ROUND(B9*0.15,0) | C10: ='Декомпозиция'!$N$2 | D10: =B10*C10
A11: ИТОГО | B11: =B9+B10 | C11: ='Декомпозиция'!$N$2 | D11: =B11*C11
A13: ⚠️ HIPAA: стоимость внешнего аудитора (~$5–20k) НЕ включена — требует отдельного бюджета.
A14: ⚠️ GPU-оборудование для on-premise (~1–2 млн ₽) — отдельная статья расходов заказчика.
A15: 📅 Рекомендуемые сроки: 6–8 месяцев при команде 3–4 BE + ML-инженер + FE + QA + DevOps.
A16: ⚠️ Качество перевода гарантируется для EN↔RU и EN↔HI. Остальные пары — best effort.
